<sdf version='1.5'>
  <model name='airfly_hexa'>
    <!-- Main body frame Airfly hexacopter  -->
    <link name='base_link'>
      <pose>0 0 0 0 0 0</pose> <!-- This pose is the visual offset of the vehicle + the reference frame -->
      <inertial>
        <pose>0.00248395293577031 0.000136495293976524 -0.174981555965809 0 0 0</pose> <!-- This pose is the center of mass of the vehicle 155.931459830594-->
        <mass>95</mass>
        <inertia>
          <ixx>2.93015030357653</ixx>
          <ixy>2.67282084525685e-05</ixy>
          <ixz>0.0449250956057515</ixz>
          <iyy>2.98862504201484</iyy>
          <iyz>6.44540809146554e-05</iyz>
          <izz>4.78028912562783</izz>
        </inertia>
      </inertial>
      <collision name='base_link_collision'>
        <pose>0 0 -0.175 0 0 0</pose> <!-- The z Axis has an offset to create a centered box for collisions https://answers.gazebosim.org//question/17457/robot-slips-after-upgrade-to-kinetic/ -->
        <geometry>
          <box>
            <size>1.944514 2.231896 0.886246</size> 
          </box>
        </geometry>
        <surface>
          <friction>
            <ode>
              <mu>100000.0</mu>
              <mu2>100000.0</mu2>
              <fdir1>1 0 0</fdir1>
              <slip1>0.0</slip1>
              <slip2>0.0</slip2>
            </ode>
          </friction>
          <contact>
            <ode>
              <min_depth>0.01</min_depth>
              <max_vel>1</max_vel>
            </ode>
          </contact>
        </surface>
      </collision>
      <visual name='base_link_visual'>
        <pose>0 0 0 0 0 0</pose>
        <geometry>
          <mesh> 
            <scale>1 1 1</scale>
            <uri>model://airfly_hexa/meshes/base_link.STL</uri>
          </mesh>
        </geometry>
        <material>
          <script>
            <name>Gazebo/DarkGrey</name>
            <uri>file://media/materials/scripts/gazebo.material</uri>
          </script>
        </material>
      </visual>
      <gravity>1</gravity>
      <velocity_decay/>
   </link>

   <!-- IMU link-->
   <link name='/imu_link'> 
      <pose>0 0 0 0 0 0</pose>
      <inertial>
        <pose>0 0 0 0 0 0</pose>
        <mass>0.015</mass>
        <inertia>
          <ixx>1e-05</ixx>
          <ixy>0</ixy>
          <ixz>0</ixz>
          <iyy>1e-05</iyy>
          <iyz>0</iyz>
          <izz>1e-05</izz>
        </inertia>
      </inertial>
    </link>
    <joint name='/imu_joint' type='revolute'>
      <child>/imu_link</child>
      <parent>base_link</parent>
      <axis>
        <xyz>1 0 0</xyz>
        <limit>
          <lower>0</lower>
          <upper>0</upper>
          <effort>0</effort>
          <velocity>0</velocity>
        </limit>
        <dynamics>
          <spring_reference>0</spring_reference>
          <spring_stiffness>0</spring_stiffness>
        </dynamics>
        <use_parent_model_frame>1</use_parent_model_frame>
      </axis>
    </joint>

    <!-- Rotor 1-->
    <link name='rotor_0'>
    <pose>0.8659 0.40285 0.25157 0.24252 0.13781 0.017864</pose>
      <inertial>
        <pose>-5.7506e-05 -0.0012881 7.3747e-05 0 0 0</pose>
        <mass>0.4177</mass>
        <inertia>
          <ixx>0.0053435</ixx>
          <ixy>-3.2435e-05</ixy>
          <ixz>-1.7561e-07</ixz>
          <iyy>0.00011193</iyy>
          <iyz>1.3276e-07</iyz>
          <izz>0.005443</izz>
        </inertia>
      </inertial>
      <collision name='rotor_0_collision'>
        <pose>0 0 0 0 0 0</pose>
        <geometry>
          <cylinder>
            <length>0.02</length>
            <radius>0.406</radius>
          </cylinder>
        </geometry>
        <surface>
          <contact>
            <ode/>
          </contact>
          <friction>
            <ode/>
          </friction>
        </surface>
      </collision>
      <visual name='rotor_0_visual'>
        <pose>0 0 0 0 0 0</pose>
        <geometry>
          <mesh>
            <scale>1 1 1</scale>
            <uri>model://airfly_hexa/meshes/rotor_1.STL</uri>
          </mesh>
        </geometry>
        <material>
          <script>
            <name>Gazebo/BlueTransparent</name>
            <uri>file://media/materials/scripts/gazebo.material</uri>
          </script>
        </material>
      </visual>
      <gravity>1</gravity>
      <velocity_decay/>
      <self_collide>0</self_collide>
    </link>
    <joint name='rotor_0_joint' type='revolute'>
      <child>rotor_0</child>
      <parent>base_link</parent>
      <pose>0 0 0 0 0 0</pose>
      <axis>
        <xyz>0 0 1</xyz>
        <limit>
          <lower>-1e+16</lower>
          <upper>1e+16</upper>
        </limit>
        <dynamics>
          <spring_reference>0</spring_reference>
          <spring_stiffness>0</spring_stiffness>
        </dynamics>
        <use_parent_model_frame>1</use_parent_model_frame>
      </axis>
    </joint>

    <!-- Rotor 2-->
    <link name='rotor_1'>
    <pose>0.85004 -0.42999 0.25919 0.167 -0.005845 2.6538</pose>
      <inertial>
        <pose>-5.7448e-05 -0.0012862 7.3696e-05 0 0 0</pose>
        <mass>0.4177</mass>
        <inertia>
          <ixx>0.0053435</ixx>
          <ixy>-3.2434e-05</ixy>
          <ixz>-1.7607e-07</ixz>
          <iyy>0.00011193</iyy>
          <iyz>1.3339e-07</iyz>
          <izz>0.005443</izz>
        </inertia>
      </inertial>
      <collision name='rotor_1_collision'>
        <pose>0 0 0 0 0 0</pose>
        <geometry>
          <cylinder>
            <length>0.02</length>
            <radius>0.406</radius>
          </cylinder>
        </geometry>
        <surface>
          <contact>
            <ode/>
          </contact>
          <friction>
            <ode/>
          </friction>
        </surface>
      </collision>
      <visual name='rotor_1_visual'>
        <pose>0 0 0 0 0 0</pose>
        <geometry>
          <mesh>
            <scale>1 1 1</scale>
            <uri>model://airfly_hexa/meshes/rotor_1.STL</uri>
          </mesh>
        </geometry>
        <material>
          <script>
            <name>Gazebo/OrangeTransparent</name>
            <uri>file://media/materials/scripts/gazebo.material</uri>
          </script>
        </material>
      </visual>
      <gravity>1</gravity>
      <velocity_decay/>
      <self_collide>0</self_collide>
    </link>
    <joint name='rotor_1_joint' type='revolute'>
      <child>rotor_1</child>
      <parent>base_link</parent>
      <pose>0 0 0 0 0 0</pose>
      <axis>
        <xyz>0 0 1</xyz>
        <limit>
          <lower>-1e+16</lower>
          <upper>1e+16</upper>
        </limit>
        <dynamics>
          <spring_reference>0</spring_reference>
          <spring_stiffness>0</spring_stiffness>
        </dynamics>
        <use_parent_model_frame>1</use_parent_model_frame>
      </axis>
    </joint>

    <!-- Rotor 3-->
    <link name='rotor_2'>
    <pose>-0.084071 -0.95131 0.25157 -0.0029981 0.27825 3.1318</pose>
      <inertial>
        <pose>-5.7506e-05 -0.0012881 7.3729e-05 0 0 0</pose>
        <mass>0.4177</mass>
        <inertia>
          <ixx>0.0053435</ixx>
          <ixy>-3.2435e-05</ixy>
          <ixz>-1.7611e-07</ixz>
          <iyy>0.00011193</iyy>
          <iyz>1.3111e-07</iyz>
          <izz>0.005443</izz>
        </inertia>
      </inertial>
      <collision name='rotor_2_collision'>
        <pose>0 0 0 0 0 0</pose>
        <geometry>
          <cylinder>
            <length>0.02</length>
            <radius>0.406</radius>
          </cylinder>
        </geometry>
        <surface>
          <contact>
            <ode/>
          </contact>
          <friction>
            <ode/>
          </friction>
        </surface>
      </collision>
      <visual name='rotor_2_visual'>
        <pose>0 0 0 0 0 0</pose>
        <geometry>
          <mesh>
            <scale>1 1 1</scale>
            <uri>model://airfly_hexa/meshes/rotor_1.STL</uri>
          </mesh>
        </geometry>
        <material>
          <script>
            <name>Gazebo/BlueTransparent</name>
            <uri>file://media/materials/scripts/gazebo.material</uri>
          </script>
        </material>
      </visual>
      <gravity>1</gravity>
      <velocity_decay/>
      <self_collide>0</self_collide>
    </link>
    <joint name='rotor_2_joint' type='revolute'>
      <child>rotor_2</child>
      <parent>base_link</parent>
      <pose>0 0 0 0 0 0</pose>
      <axis>
        <xyz>0 0 1</xyz>
        <limit>
          <lower>-1e+16</lower>
          <upper>1e+16</upper>
        </limit>
        <dynamics>
          <spring_reference>0</spring_reference>
          <spring_stiffness>0</spring_stiffness>
        </dynamics>
        <use_parent_model_frame>1</use_parent_model_frame>
      </axis>
    </joint>

    <!-- Rotor 4-->
    <link name='rotor_3'>
    <pose>-0.7974 -0.52116 0.25919 0.14504 0.083268 0.0071482</pose>
      <inertial>
        <pose>-5.7507e-05 -0.0012881 7.3743e-05 0 0 0</pose>
        <mass>0.4177</mass>
        <inertia>
          <ixx>0.0053435</ixx>
          <ixy>-3.2434e-05</ixy>
          <ixz>-1.756e-07</ixz>
          <iyy>0.00011193</iyy>
          <iyz>1.3269e-07</iyz>
          <izz>0.005443</izz>
        </inertia>
      </inertial>
      <collision name='rotor_3_collision'>
        <pose>0 0 0 0 0 0</pose>
        <geometry>
          <cylinder>
            <length>0.02</length>
            <radius>0.406</radius>
          </cylinder>
        </geometry>
        <surface>
          <contact>
            <ode/>
          </contact>
          <friction>
            <ode/>
          </friction>
        </surface>
      </collision>
      <visual name='rotor_3_visual'>
        <pose>0 0 0 0 0 0</pose>
        <geometry>
          <mesh>
            <scale>1 1 1</scale>
            <uri>model://airfly_hexa/meshes/rotor_1.STL</uri>
          </mesh>
        </geometry>
        <material>
          <script>
            <name>Gazebo/OrangeTransparent</name>
            <uri>file://media/materials/scripts/gazebo.material</uri>
          </script>
        </material>
      </visual>
      <gravity>1</gravity>
      <velocity_decay/>
      <self_collide>0</self_collide>
    </link>
    <joint name='rotor_3_joint' type='revolute'>
      <child>rotor_3</child>
      <parent>base_link</parent>
      <pose>0 0 0 0 0 0</pose>
      <axis>
        <xyz>0 0 1</xyz>
        <limit>
          <lower>-1e+16</lower>
          <upper>1e+16</upper>
        </limit>
        <dynamics>
          <spring_reference>0</spring_reference>
          <spring_stiffness>0</spring_stiffness>
        </dynamics>
        <use_parent_model_frame>1</use_parent_model_frame>
      </axis>
    </joint>

    <!-- Rotor 5-->
    <link name='rotor_4'>
    <pose>-0.78182 0.54846 0.25157 -0.24255 0.13775 -0.01577</pose>
      <inertial> 
        <pose>-5.7509e-05 -0.0012881 7.3721e-05 0 0 0</pose>
        <mass>0.4177</mass>
        <inertia>
          <ixx>0.0053435</ixx>
          <ixy>-3.2435e-05</ixy>
          <ixz>-1.7558e-07</ixz>
          <iyy>0.00011193</iyy>
          <iyz>1.3236e-07</iyz>
          <izz>0.005443</izz>
        </inertia>
      </inertial>
      <collision name='rotor_4_collision'>
        <pose>0 0 0 0 0 0</pose>
        <geometry>
          <cylinder>
            <length>0.02</length>
            <radius>0.406</radius>
          </cylinder>
        </geometry>
        <surface>
          <contact>
            <ode/>
          </contact>
          <friction>
            <ode/>
          </friction>
        </surface>
      </collision>
      <visual name='rotor_4_visual'>
        <pose>0 0 0 0 0 0</pose>
        <geometry>
          <mesh>
            <scale>1 1 1</scale>
            <uri>model://airfly_hexa/meshes/rotor_1.STL</uri>
          </mesh>
        </geometry>
        <material>
          <script>
            <name>Gazebo/BlueTransparent</name>
            <uri>file://media/materials/scripts/gazebo.material</uri>
          </script>
        </material>
      </visual>
      <gravity>1</gravity>
      <velocity_decay/>
      <self_collide>0</self_collide>
    </link>
    <joint name='rotor_4_joint' type='revolute'>
      <child>rotor_4</child>
      <parent>base_link</parent>
      <pose>0 0 0 0 0 0</pose>
      <axis>
        <xyz>0 0 1</xyz>
        <limit>
          <lower>-1e+16</lower>
          <upper>1e+16</upper>
        </limit>
        <dynamics>
          <spring_reference>0</spring_reference>
          <spring_stiffness>0</spring_stiffness>
        </dynamics>
        <use_parent_model_frame>1</use_parent_model_frame>
      </axis>
    </joint>

    <!-- Rotor 6-->
    <link name='rotor_5'>
    <pose>-0.052635 0.95115 0.25919 -2.5657e-05 -0.1671 0.0013258</pose>
      <inertial>
        <pose>-5.7509e-05 -0.0012881 7.3721e-05 0 0 0</pose>
        <mass>0.4177</mass>
        <inertia>
          <ixx>0.0053435</ixx>
          <ixy>-3.2435e-05</ixy>
          <ixz>-1.7558e-07</ixz>
          <iyy>0.00011193</iyy>
          <iyz>1.3236e-07</iyz>
          <izz>0.005443</izz>
        </inertia>
      </inertial>
      <collision name='rotor_5_collision'>
        <pose>0 0 0 0 0 0</pose>
        <geometry>
          <cylinder>
            <length>0.02</length>
            <radius>0.406</radius>
          </cylinder>
        </geometry>
        <surface>
          <contact>
            <ode/>
          </contact>
          <friction>
            <ode/>
          </friction>
        </surface>
      </collision>
      <visual name='rotor_5_visual'>
        <pose>0 0 0 0 0 0</pose>
        <geometry>
          <mesh>
            <scale>1 1 1</scale>
            <uri>model://airfly_hexa/meshes/rotor_1.STL</uri>
          </mesh>
        </geometry>
        <material>
          <script>
            <name>Gazebo/OrangeTransparent</name>
            <uri>file://media/materials/scripts/gazebo.material</uri>
          </script>
        </material>
      </visual>
      <gravity>1</gravity>
      <velocity_decay/>
      <self_collide>0</self_collide>
    </link>
    <joint name='rotor_5_joint' type='revolute'>
      <child>rotor_5</child>
      <parent>base_link</parent>
      <pose>0 0 0 0 0 0</pose>
      <axis>
        <xyz>0 0 1</xyz>
        <limit>
          <lower>-1e+16</lower>
          <upper>1e+16</upper>
        </limit>
        <dynamics>
          <spring_reference>0</spring_reference>
          <spring_stiffness>0</spring_stiffness>
        </dynamics>
        <use_parent_model_frame>1</use_parent_model_frame>
      </axis>
    </joint>

    <!-- Rosbag Plugin-->
    <plugin name='rosbag' filename='libgazebo_multirotor_base_plugin.so'>
      <robotNamespace/>
      <linkName>base_link</linkName>
      <rotorVelocitySlowdownSim>10</rotorVelocitySlowdownSim>
    </plugin>

    <plugin name='front_right_motor_model' filename='libgazebo_motor_model.so'>
      <robotNamespace></robotNamespace>
      <jointName>rotor_1_joint</jointName>
      <linkName>rotor_1</linkName>
      <turningDirection>ccw</turningDirection>
      <timeConstantUp>0.0125</timeConstantUp>
      <timeConstantDown>0.025</timeConstantDown>
      <maxRotVelocity>470</maxRotVelocity>
      <motorConstant>12.010474e-04</motorConstant>
      <momentConstant>0.06</momentConstant>
      <commandSubTopic>/gazebo/command/motor_speed</commandSubTopic>
      <motorNumber>4</motorNumber>
      <rotorDragCoefficient>0.002557889</rotorDragCoefficient>
      <rollingMomentCoefficient>3.172e-06</rollingMomentCoefficient>
      <motorSpeedPubTopic>/motor_speed/4</motorSpeedPubTopic>
      <rotorVelocitySlowdownSim>4</rotorVelocitySlowdownSim>
    </plugin>

    <plugin name='back_left_motor_model' filename='libgazebo_motor_model.so'>
      <robotNamespace></robotNamespace>
      <jointName>rotor_4_joint</jointName>
      <linkName>rotor_4</linkName>
      <turningDirection>cw</turningDirection>
      <timeConstantUp>0.0125</timeConstantUp>
      <timeConstantDown>0.025</timeConstantDown>
      <maxRotVelocity>470</maxRotVelocity>
      <motorConstant>12.010474e-04</motorConstant>
      <momentConstant>0.06</momentConstant>
      <commandSubTopic>/gazebo/command/motor_speed</commandSubTopic>
      <motorNumber>5</motorNumber>
      <rotorDragCoefficient>0.002557889</rotorDragCoefficient>
      <rollingMomentCoefficient>3.172e-06</rollingMomentCoefficient>
      <motorSpeedPubTopic>/motor_speed/5</motorSpeedPubTopic>
      <rotorVelocitySlowdownSim>4</rotorVelocitySlowdownSim>
    </plugin>

    <plugin name='front_left_motor_model' filename='libgazebo_motor_model.so'>
      <robotNamespace></robotNamespace>
      <jointName>rotor_0_joint</jointName>
      <linkName>rotor_0</linkName>
      <turningDirection>cw</turningDirection>
      <timeConstantUp>0.0125</timeConstantUp>
      <timeConstantDown>0.025</timeConstantDown>
      <maxRotVelocity>470</maxRotVelocity>
      <motorConstant>12.010474e-04</motorConstant>
      <momentConstant>0.06</momentConstant>
      <commandSubTopic>/gazebo/command/motor_speed</commandSubTopic>
      <motorNumber>2</motorNumber>
      <rotorDragCoefficient>0.002557889</rotorDragCoefficient>
      <rollingMomentCoefficient>3.172e-06</rollingMomentCoefficient>
      <motorSpeedPubTopic>/motor_speed/2</motorSpeedPubTopic>
      <rotorVelocitySlowdownSim>4</rotorVelocitySlowdownSim>
    </plugin>

    <plugin name='back_right_motor_model' filename='libgazebo_motor_model.so'>
      <robotNamespace></robotNamespace>
      <jointName>rotor_3_joint</jointName>
      <linkName>rotor_3</linkName>
      <turningDirection>ccw</turningDirection>
      <timeConstantUp>0.0125</timeConstantUp>
      <timeConstantDown>0.025</timeConstantDown>
      <maxRotVelocity>470</maxRotVelocity>
      <motorConstant>12.010474e-04</motorConstant>
      <momentConstant>0.06</momentConstant>
      <commandSubTopic>/gazebo/command/motor_speed</commandSubTopic>
      <motorNumber>3</motorNumber>
      <rotorDragCoefficient>0.002557889</rotorDragCoefficient>
      <rollingMomentCoefficient>3.172e-06</rollingMomentCoefficient>
      <motorSpeedPubTopic>/motor_speed/3</motorSpeedPubTopic>
      <rotorVelocitySlowdownSim>4</rotorVelocitySlowdownSim>
    </plugin>

    <plugin name='back_left_motor_model' filename='libgazebo_motor_model.so'>
      <robotNamespace></robotNamespace>
      <jointName>rotor_2_joint</jointName>
      <linkName>rotor_2</linkName>
      <turningDirection>cw</turningDirection>
      <timeConstantUp>0.0125</timeConstantUp>
      <timeConstantDown>0.025</timeConstantDown>
      <maxRotVelocity>470</maxRotVelocity>
      <motorConstant>12.010474e-04</motorConstant>
      <momentConstant>0.06</momentConstant>
      <commandSubTopic>/gazebo/command/motor_speed</commandSubTopic>
      <motorNumber>0</motorNumber>
      <rotorDragCoefficient>0.002557889</rotorDragCoefficient>
      <rollingMomentCoefficient>3.172e-06</rollingMomentCoefficient>
      <motorSpeedPubTopic>/motor_speed/0</motorSpeedPubTopic>
      <rotorVelocitySlowdownSim>4</rotorVelocitySlowdownSim>
    </plugin>

    <plugin name='front_left_motor_model' filename='libgazebo_motor_model.so'>
      <robotNamespace></robotNamespace>
      <jointName>rotor_5_joint</jointName>
      <linkName>rotor_5</linkName>
      <turningDirection>ccw</turningDirection>
      <timeConstantUp>0.0125</timeConstantUp>
      <timeConstantDown>0.025</timeConstantDown>
      <maxRotVelocity>470</maxRotVelocity>
      <motorConstant>12.010474e-04</motorConstant>
      <momentConstant>0.06</momentConstant>
      <commandSubTopic>/gazebo/command/motor_speed</commandSubTopic>
      <motorNumber>1</motorNumber>
      <rotorDragCoefficient>0.002557889</rotorDragCoefficient>
      <rollingMomentCoefficient>3.172e-06</rollingMomentCoefficient>
      <motorSpeedPubTopic>/motor_speed/1</motorSpeedPubTopic>
      <rotorVelocitySlowdownSim>4</rotorVelocitySlowdownSim>
    </plugin>

    <!-- GPS Plugin-->
    <plugin name='gps_plugin' filename='libgazebo_gps_plugin.so'>
      <robotNamespace/>
      <gpsNoise>true</gpsNoise>
    </plugin>

    <!-- Magnetometer Plugin-->
    <plugin name='magnetometer_plugin' filename='libgazebo_magnetometer_plugin.so'>
      <robotNamespace/>
      <pubRate>20</pubRate>
      <noiseDensity>0.0004</noiseDensity>
      <randomWalk>6.4e-06</randomWalk>
      <biasCorrelationTime>600</biasCorrelationTime>
      <magTopic>/mag</magTopic>
    </plugin>

    <!-- Barometer Plugin-->
    <plugin name='barometer_plugin' filename='libgazebo_barometer_plugin.so'>
      <robotNamespace/>
      <pubRate>10</pubRate>
      <baroTopic>/baro</baroTopic>
    </plugin>

    <!-- Mavlink Plugin-->
    <plugin name='mavlink_interface' filename='libgazebo_mavlink_interface.so'>
      <robotNamespace/>
      <imuSubTopic>/imu</imuSubTopic>
      <gpsSubTopic>/gps</gpsSubTopic>
      <magSubTopic>/mag</magSubTopic>
      <baroSubTopic>/baro</baroSubTopic>
      <mavlink_addr>INADDR_ANY</mavlink_addr>
      <mavlink_udp_port>14560</mavlink_udp_port>
      <mavlink_tcp_port>4560</mavlink_tcp_port>
      <serialEnabled>0</serialEnabled>
      <serialDevice>/dev/ttyACM0</serialDevice>
      <baudRate>921600</baudRate>
      <qgc_addr>INADDR_ANY</qgc_addr>
      <qgc_udp_port>14550</qgc_udp_port>
      <sdk_addr>INADDR_ANY</sdk_addr>
      <sdk_udp_port>14540</sdk_udp_port>
      <hil_mode>0</hil_mode>
      <hil_state_level>0</hil_state_level>
      <enable_lockstep>0</enable_lockstep>
      <use_tcp>1</use_tcp>
      <vehicle_is_tailsitter>0</vehicle_is_tailsitter>
      <send_vision_estimation>1</send_vision_estimation>
      <send_odometry>0</send_odometry>
      <motorSpeedCommandPubTopic>/gazebo/command/motor_speed</motorSpeedCommandPubTopic>
      <control_channels>
        <channel name='rotor0'>
          <input_index>0</input_index>
          <input_offset>0</input_offset>
          <input_scaling>470</input_scaling>
          <zero_position_disarmed>0</zero_position_disarmed>
          <zero_position_armed>100</zero_position_armed>
          <joint_control_type>velocity</joint_control_type>
          <joint_name>rotor_2_joint</joint_name>
        </channel>
        <channel name='rotor1'>
          <input_index>1</input_index>
          <input_offset>0</input_offset>
          <input_scaling>470</input_scaling>
          <zero_position_disarmed>0</zero_position_disarmed>
          <zero_position_armed>100</zero_position_armed>
          <joint_control_type>velocity</joint_control_type>
          <joint_name>rotor_5_joint</joint_name>
        </channel>
        <channel name='rotor2'>
          <input_index>2</input_index>
          <input_offset>0</input_offset>
          <input_scaling>470</input_scaling>
          <zero_position_disarmed>0</zero_position_disarmed>
          <zero_position_armed>100</zero_position_armed>
          <joint_control_type>velocity</joint_control_type>
          <joint_name>rotor_0_joint</joint_name>
        </channel>
        <channel name='rotor3'>
          <input_index>3</input_index>
          <input_offset>0</input_offset>
          <input_scaling>470</input_scaling>
          <zero_position_disarmed>0</zero_position_disarmed>
          <zero_position_armed>100</zero_position_armed>
          <joint_control_type>velocity</joint_control_type>
          <joint_name>rotor_3_joint</joint_name>
        </channel>
        <channel name='rotor4'>
          <input_index>4</input_index>
          <input_offset>0</input_offset>
          <input_scaling>470</input_scaling>
          <zero_position_disarmed>0</zero_position_disarmed>
          <zero_position_armed>100</zero_position_armed>
          <joint_control_type>velocity</joint_control_type>
          <joint_name>rotor_1_joint</joint_name>
        </channel>
        <channel name='rotor5'>
          <input_index>5</input_index>
          <input_offset>0</input_offset>
          <input_scaling>470</input_scaling>
          <zero_position_disarmed>0</zero_position_disarmed>
          <zero_position_armed>100</zero_position_armed>
          <joint_control_type>velocity</joint_control_type>
          <joint_name>rotor_4_joint</joint_name>
        </channel>
      </control_channels>
    </plugin>
    <static>0</static>

    <!-- IMU plugin-->
    <plugin name='rotors_gazebo_imu_plugin' filename='libgazebo_imu_plugin.so'>
      <robotNamespace/>
      <linkName>/imu_link</linkName>
      <imuTopic>/imu</imuTopic>
      <gyroscopeNoiseDensity>0.0003394</gyroscopeNoiseDensity>
      <gyroscopeRandomWalk>3.8785e-05</gyroscopeRandomWalk>
      <gyroscopeBiasCorrelationTime>1000.0</gyroscopeBiasCorrelationTime>
      <gyroscopeTurnOnBiasSigma>0.0087</gyroscopeTurnOnBiasSigma>
      <accelerometerNoiseDensity>0.004</accelerometerNoiseDensity>
      <accelerometerRandomWalk>0.006</accelerometerRandomWalk>
      <accelerometerBiasCorrelationTime>300.0</accelerometerBiasCorrelationTime>
      <accelerometerTurnOnBiasSigma>0.196</accelerometerTurnOnBiasSigma>
    </plugin>

    <!--Ground Truth
    <plugin name="ground_truth" filename="libgazebo_ros_p3d.so">
      <frameName>map</frameName>
      <bodyName>base_link</bodyName>
      <topicName>/odom</topicName>
      <updateRate>30.0</updateRate>
      <xyzOffset>0 0 -0.1975016</xyzOffset>
      <rpyOffset>0 0 0</rpyOffset>
    </plugin> -->


  </model>
</sdf>

