<?xml version="1.0" ?>
<!-- =================================================================================== -->
<!-- |    This document was autogenerated by xacro from /home/sherlock/Firmware/Tools/sitl_gazebo/models/airfly_hexa/urdf/hexa_base.xacro | -->
<!-- |    EDITING THIS FILE BY HAND IS NOT RECOMMENDED                                 | -->
<!-- =================================================================================== -->
<robot name="airfly_hexa" xmlns:xacro="http://ros.org/wiki/xacro">
  <!-- Properties that can be assigned at build time as arguments.
  Is there a reason not to make all properties arguments?
  -->
  <!-- The following causes segfault with multiple vehicles if defaults to true!!! -->
  <!-- macros for gazebo plugins, sensors -->
  <!-- Macro to add logging to a bag file. -->
  <!-- Macro to add a camera. -->
  <!-- Macro to add a LiDAR. -->
  <!-- Macro to add the gps_plugin. -->
  <!-- Macro to add the magnetometer_plugin. -->
  <!-- Macro to add Ground Truth plugin -->
  <!-- Macro to add the barometer_plugin. -->
  <!-- Macro to add the mavlink interface. -->
  <!-- Macro to add an IMU. -->
  <!-- Macro to add the wind plugin. -->
  <!-- Instantiate Hexacopter "mechanics" -->
  <!-- Properties -->
  <!-- [kg] -->
  <!-- [m] -->
  <!-- [m] -->
  <!-- [m] -->
  <!-- [m] -->
  <!-- [kg] -->
  <!-- [m] -->
  <!-- [m] -->
  <!-- [kg.m/s^2] -->
  <!-- [m] -->
  <!-- [s] -->
  <!-- [s] -->
  <!-- [rad/s] -->
  <!-- Property Blocks for the Base link -->
  <!-- inertia of rotor 0 -->
  <!-- inertia of rotor 1 -->
  <!-- inertia of rotor 2 -->
  <!-- inertia of rotor 3 -->
  <!-- inertia of rotor 4 -->
  <!-- inertia of rotor 5 -->
  <!-- Included URDF Files -->
  <!-- Main multirotor link -->
  <!-- Rotor joint and link -->
  <!-- Instantiate multirotor_base_macro once -->
  <link name="base_link"/>
  <joint name="base_joint" type="fixed">
    <origin rpy="0 0 0" xyz="0 0 0"/>
    <parent link="base_link"/>
    <child link="base_link_inertia"/>
  </joint>
  <link name="base_link_inertia">
    <inertial>
      <mass value="95"/>
      <!-- [kg] -->
      <origin xyz="0.00248395293577031 0.000136495293976524 -0.174981555965809"/>
      <inertia ixx="2.93015030357653" ixy="2.67282084525685e-05" ixz="0.0449250956057515" iyy="2.98862504201484" iyz="6.44540809146554e-05" izz="4.78028912562783"/>
    </inertial>
    <visual>
      <origin rpy="0 0 0" xyz="0 0 0"/>
      <geometry>
        <mesh filename="package://airfly_hexa/meshes/base_link.STL" scale="1 1 1"/>
      </geometry>
    </visual>
    <collision>
      <origin rpy="0 0 0" xyz="0 0 -0.175"/>
      <geometry>
        <box size="1.944514 2.231896 0.886246"/>
        <!-- [m] [m] [m] -->
      </geometry>
    </collision>
  </link>
  <!-- attach multirotor_base_plugin to the base_link -->
  <gazebo>
    <plugin filename="libgazebo_multirotor_base_plugin.so" name="rosbag">
      <robotNamespace></robotNamespace>
      <linkName>base_link</linkName>
      <rotorVelocitySlowdownSim>3</rotorVelocitySlowdownSim>
    </plugin>
  </gazebo>
  <gazebo reference="base_link">
    <material>Gazebo/DarkGrey</material>
    <collision name="base_link_inertia_collision">
      <surface>
        <friction>
          <ode>
            <mu>100000.0</mu>
            <mu2>100000.0</mu2>
            <fdir1>1 0 0</fdir1>
            <slip1>0.0</slip1>
            <slip2>0.0</slip2>
          </ode>
        </friction>
        <contact>
          <ode>
            <min_depth>0.01</min_depth>
            <max_vel>1.0</max_vel>
          </ode>
        </contact>
      </surface>
    </collision>
  </gazebo>
  <!-- Instantiate rotor 4 rpy="0.167 -0.005845 2.6538" -->
  <joint name="rotor_4_joint" type="continuous">
    <origin rpy="0.167 -0.005845 2.6538" xyz="0.85004 -0.42999 0.25919"/>
    <axis xyz="0.082997 0.144137 0.986071"/>
    <parent link="base_link"/>
    <child link="rotor_4"/>
  </joint>
  <link name="rotor_4">
    <inertial>
      <mass value="0.4177"/>
      <!-- [kg] -->
      <inertia ixx="0.0053435" ixy="-3.2434e-05" ixz="-1.7607e-07" iyy="0.00011193" iyz="1.3339e-07" izz="0.005443"/>
    </inertial>
    <visual>
      <geometry>
        <mesh filename="package://airfly_hexa/meshes/rotor_1.STL" scale="1 1 1"/>
      </geometry>
    </visual>
    <collision>
      <geometry>
        <cylinder length="0.02" radius="0.406"/>
        <!-- [m] -->
      </geometry>
    </collision>
  </link>
  <gazebo>
    <plugin filename="libgazebo_motor_model.so" name="front_right_motor_model">
      <robotNamespace></robotNamespace>
      <jointName>rotor_4_joint</jointName>
      <linkName>rotor_4</linkName>
      <turningDirection>ccw</turningDirection>
      <timeConstantUp>0.0125</timeConstantUp>
      <timeConstantDown>0.025</timeConstantDown>
      <maxRotVelocity>470</maxRotVelocity>
      <motorConstant>0.0012010474</motorConstant>
      <momentConstant>0.06</momentConstant>
      <commandSubTopic>/gazebo/command/motor_speed</commandSubTopic>
      <motorNumber>4</motorNumber>
      <rotorDragCoefficient>0.002557889</rotorDragCoefficient>
      <rollingMomentCoefficient>3.172e-06</rollingMomentCoefficient>
      <motorSpeedPubTopic>/motor_speed/4</motorSpeedPubTopic>
      <rotorVelocitySlowdownSim>3</rotorVelocitySlowdownSim>
      <!--
        <gazebo_joint_control_pid>
          <p>0.1</p>
          <i>0</i>
          <d>0</d>
          <iMax>0</iMax>
          <iMin>0</iMin>
          <cmdMax>3</cmdMax>
          <cmdMin>-3</cmdMin>
        </gazebo_joint_control_pid>
      -->
    </plugin>
  </gazebo>
  <gazebo reference="rotor_4">
    <material>Gazebo/OrangeTransparent</material>
  </gazebo>
  <!-- Instantiate rotor 5 rpy="-0.24255 0.13775 -0.01577" -->
  <joint name="rotor_5_joint" type="continuous">
    <origin rpy="-0.24255 0.13775 -0.01577" xyz="-0.78182 0.54846 0.25157"/>
    <axis xyz="-0.137066 -0.238047 0.961533"/>
    <parent link="base_link"/>
    <child link="rotor_5"/>
  </joint>
  <link name="rotor_5">
    <inertial>
      <mass value="0.4177"/>
      <!-- [kg] -->
      <inertia ixx="0.0053435" ixy="-3.2435e-05" ixz="-1.7558e-07" iyy="0.00011193" iyz="1.3236e-07" izz="0.005443"/>
    </inertial>
    <visual>
      <geometry>
        <mesh filename="package://airfly_hexa/meshes/rotor_1.STL" scale="1 1 1"/>
      </geometry>
    </visual>
    <collision>
      <geometry>
        <cylinder length="0.02" radius="0.406"/>
        <!-- [m] -->
      </geometry>
    </collision>
  </link>
  <gazebo>
    <plugin filename="libgazebo_motor_model.so" name="back_left_motor_model">
      <robotNamespace></robotNamespace>
      <jointName>rotor_5_joint</jointName>
      <linkName>rotor_5</linkName>
      <turningDirection>cw</turningDirection>
      <timeConstantUp>0.0125</timeConstantUp>
      <timeConstantDown>0.025</timeConstantDown>
      <maxRotVelocity>470</maxRotVelocity>
      <motorConstant>0.0012010474</motorConstant>
      <momentConstant>0.06</momentConstant>
      <commandSubTopic>/gazebo/command/motor_speed</commandSubTopic>
      <motorNumber>5</motorNumber>
      <rotorDragCoefficient>0.002557889</rotorDragCoefficient>
      <rollingMomentCoefficient>3.172e-06</rollingMomentCoefficient>
      <motorSpeedPubTopic>/motor_speed/5</motorSpeedPubTopic>
      <rotorVelocitySlowdownSim>3</rotorVelocitySlowdownSim>
      <!--
        <gazebo_joint_control_pid>
          <p>0.1</p>
          <i>0</i>
          <d>0</d>
          <iMax>0</iMax>
          <iMin>0</iMin>
          <cmdMax>3</cmdMax>
          <cmdMin>-3</cmdMin>
        </gazebo_joint_control_pid>
      -->
    </plugin>
  </gazebo>
  <gazebo reference="rotor_5">
    <material>Gazebo/BlueTransparent</material>
  </gazebo>
  <!-- Instantiate rotor 2 rpy="0.24252 0.13781 0.017864" -->
  <joint name="rotor_2_joint" type="continuous">
    <origin rpy="0.24252 0.13781 0.017864" xyz="0.8659 0.40285 0.25157"/>
    <axis xyz="-0.137623 0.237729 0.961533"/>
    <parent link="base_link"/>
    <child link="rotor_2"/>
  </joint>
  <link name="rotor_2">
    <inertial>
      <mass value="0.4177"/>
      <!-- [kg] -->
      <inertia ixx="0.0053435" ixy="-3.2435e-05" ixz="-1.7561e-07" iyy="0.00011193" iyz="1.3276e-07" izz="0.005443"/>
    </inertial>
    <visual>
      <geometry>
        <mesh filename="package://airfly_hexa/meshes/rotor_1.STL" scale="1 1 1"/>
      </geometry>
    </visual>
    <collision>
      <geometry>
        <cylinder length="0.02" radius="0.406"/>
        <!-- [m] -->
      </geometry>
    </collision>
  </link>
  <gazebo>
    <plugin filename="libgazebo_motor_model.so" name="front_left_motor_model">
      <robotNamespace></robotNamespace>
      <jointName>rotor_2_joint</jointName>
      <linkName>rotor_2</linkName>
      <turningDirection>cw</turningDirection>
      <timeConstantUp>0.0125</timeConstantUp>
      <timeConstantDown>0.025</timeConstantDown>
      <maxRotVelocity>470</maxRotVelocity>
      <motorConstant>0.0012010474</motorConstant>
      <momentConstant>0.06</momentConstant>
      <commandSubTopic>/gazebo/command/motor_speed</commandSubTopic>
      <motorNumber>2</motorNumber>
      <rotorDragCoefficient>0.002557889</rotorDragCoefficient>
      <rollingMomentCoefficient>3.172e-06</rollingMomentCoefficient>
      <motorSpeedPubTopic>/motor_speed/2</motorSpeedPubTopic>
      <rotorVelocitySlowdownSim>3</rotorVelocitySlowdownSim>
      <!--
        <gazebo_joint_control_pid>
          <p>0.1</p>
          <i>0</i>
          <d>0</d>
          <iMax>0</iMax>
          <iMin>0</iMin>
          <cmdMax>3</cmdMax>
          <cmdMin>-3</cmdMin>
        </gazebo_joint_control_pid>
      -->
    </plugin>
  </gazebo>
  <gazebo reference="rotor_2">
    <material>Gazebo/BlueTransparent</material>
  </gazebo>
  <!-- Instantiate rotor 3 rpy="0.14504 0.083268 0.0071482" -->
  <joint name="rotor_3_joint" type="continuous">
    <origin rpy="0.14504 0.083268 0.0071482" xyz="-0.7974 -0.52116 0.25919"/>
    <axis xyz="-0.08333 0.14394 0.986072"/>
    <parent link="base_link"/>
    <child link="rotor_3"/>
  </joint>
  <link name="rotor_3">
    <inertial>
      <mass value="0.4177"/>
      <!-- [kg] -->
      <inertia ixx="0.0053435" ixy="-3.2434e-05" ixz="-1.756e-07" iyy="0.00011193" iyz="1.3269e-07" izz="0.005443"/>
    </inertial>
    <visual>
      <geometry>
        <mesh filename="package://airfly_hexa/meshes/rotor_1.STL" scale="1 1 1"/>
      </geometry>
    </visual>
    <collision>
      <geometry>
        <cylinder length="0.02" radius="0.406"/>
        <!-- [m] -->
      </geometry>
    </collision>
  </link>
  <gazebo>
    <plugin filename="libgazebo_motor_model.so" name="back_right_motor_model">
      <robotNamespace></robotNamespace>
      <jointName>rotor_3_joint</jointName>
      <linkName>rotor_3</linkName>
      <turningDirection>ccw</turningDirection>
      <timeConstantUp>0.0125</timeConstantUp>
      <timeConstantDown>0.025</timeConstantDown>
      <maxRotVelocity>470</maxRotVelocity>
      <motorConstant>0.0012010474</motorConstant>
      <momentConstant>0.06</momentConstant>
      <commandSubTopic>/gazebo/command/motor_speed</commandSubTopic>
      <motorNumber>3</motorNumber>
      <rotorDragCoefficient>0.002557889</rotorDragCoefficient>
      <rollingMomentCoefficient>3.172e-06</rollingMomentCoefficient>
      <motorSpeedPubTopic>/motor_speed/3</motorSpeedPubTopic>
      <rotorVelocitySlowdownSim>3</rotorVelocitySlowdownSim>
      <!--
        <gazebo_joint_control_pid>
          <p>0.1</p>
          <i>0</i>
          <d>0</d>
          <iMax>0</iMax>
          <iMin>0</iMin>
          <cmdMax>3</cmdMax>
          <cmdMin>-3</cmdMin>
        </gazebo_joint_control_pid>
      -->
    </plugin>
  </gazebo>
  <gazebo reference="rotor_3">
    <material>Gazebo/OrangeTransparent</material>
  </gazebo>
  <!-- Instantiate rotor 0 rpy="-0.0029981 0.27825 3.1318" -->
  <joint name="rotor_0_joint" type="continuous">
    <origin rpy="-0.0029981 0.27825 3.1318" xyz="-0.084071 -0.95131 0.25157"/>
    <axis xyz="-0.274688 -0.000308 0.961533"/>
    <parent link="base_link"/>
    <child link="rotor_0"/>
  </joint>
  <link name="rotor_0">
    <inertial>
      <mass value="0.4177"/>
      <!-- [kg] -->
      <inertia ixx="0.0053435" ixy="-3.2435e-05" ixz="-1.7611e-07" iyy="0.00011193" iyz="1.3111e-07" izz="0.005443"/>
    </inertial>
    <visual>
      <geometry>
        <mesh filename="package://airfly_hexa/meshes/rotor_1.STL" scale="1 1 1"/>
      </geometry>
    </visual>
    <collision>
      <geometry>
        <cylinder length="0.02" radius="0.406"/>
        <!-- [m] -->
      </geometry>
    </collision>
  </link>
  <gazebo>
    <plugin filename="libgazebo_motor_model.so" name="back_left_motor_model">
      <robotNamespace></robotNamespace>
      <jointName>rotor_0_joint</jointName>
      <linkName>rotor_0</linkName>
      <turningDirection>cw</turningDirection>
      <timeConstantUp>0.0125</timeConstantUp>
      <timeConstantDown>0.025</timeConstantDown>
      <maxRotVelocity>470</maxRotVelocity>
      <motorConstant>0.0012010474</motorConstant>
      <momentConstant>0.06</momentConstant>
      <commandSubTopic>/gazebo/command/motor_speed</commandSubTopic>
      <motorNumber>0</motorNumber>
      <rotorDragCoefficient>0.002557889</rotorDragCoefficient>
      <rollingMomentCoefficient>3.172e-06</rollingMomentCoefficient>
      <motorSpeedPubTopic>/motor_speed/0</motorSpeedPubTopic>
      <rotorVelocitySlowdownSim>3</rotorVelocitySlowdownSim>
      <!--
        <gazebo_joint_control_pid>
          <p>0.1</p>
          <i>0</i>
          <d>0</d>
          <iMax>0</iMax>
          <iMin>0</iMin>
          <cmdMax>3</cmdMax>
          <cmdMin>-3</cmdMin>
        </gazebo_joint_control_pid>
      -->
    </plugin>
  </gazebo>
  <gazebo reference="rotor_0">
    <material>Gazebo/BlueTransparent</material>
  </gazebo>
  <!-- Instantiate rotor 1 rpy="-2.5657e-05 -0.1671 0.0013258" -->
  <joint name="rotor_1_joint" type="continuous">
    <origin rpy="-2.5657e-05 -0.1671 0.0013258" xyz="-0.052635 0.95115 0.25919"/>
    <axis xyz="0.166323 0.000195 0.986071"/>
    <parent link="base_link"/>
    <child link="rotor_1"/>
  </joint>
  <link name="rotor_1">
    <inertial>
      <mass value="0.4177"/>
      <!-- [kg] -->
      <inertia ixx="0.0053435" ixy="-3.2435e-05" ixz="-1.7558e-07" iyy="0.00011193" iyz="1.3236e-07" izz="0.005443"/>
    </inertial>
    <visual>
      <geometry>
        <mesh filename="package://airfly_hexa/meshes/rotor_1.STL" scale="1 1 1"/>
      </geometry>
    </visual>
    <collision>
      <geometry>
        <cylinder length="0.02" radius="0.406"/>
        <!-- [m] -->
      </geometry>
    </collision>
  </link>
  <gazebo>
    <plugin filename="libgazebo_motor_model.so" name="back_right_motor_model">
      <robotNamespace></robotNamespace>
      <jointName>rotor_1_joint</jointName>
      <linkName>rotor_1</linkName>
      <turningDirection>ccw</turningDirection>
      <timeConstantUp>0.0125</timeConstantUp>
      <timeConstantDown>0.025</timeConstantDown>
      <maxRotVelocity>470</maxRotVelocity>
      <motorConstant>0.0012010474</motorConstant>
      <momentConstant>0.06</momentConstant>
      <commandSubTopic>/gazebo/command/motor_speed</commandSubTopic>
      <motorNumber>1</motorNumber>
      <rotorDragCoefficient>0.002557889</rotorDragCoefficient>
      <rollingMomentCoefficient>3.172e-06</rollingMomentCoefficient>
      <motorSpeedPubTopic>/motor_speed/1</motorSpeedPubTopic>
      <rotorVelocitySlowdownSim>3</rotorVelocitySlowdownSim>
      <!--
        <gazebo_joint_control_pid>
          <p>0.1</p>
          <i>0</i>
          <d>0</d>
          <iMax>0</iMax>
          <iMin>0</iMin>
          <cmdMax>3</cmdMax>
          <cmdMin>-3</cmdMin>
        </gazebo_joint_control_pid>
      -->
    </plugin>
  </gazebo>
  <gazebo reference="rotor_1">
    <material>Gazebo/OrangeTransparent</material>
  </gazebo>
  <!-- Wind Plugin -->
  <!-- Instantiate gps plugin. -->
  <gazebo>
    <plugin filename="libgazebo_gps_plugin.so" name="gps_plugin">
      <robotNamespace></robotNamespace>
      <gpsNoise>true</gpsNoise>
    </plugin>
  </gazebo>
  <!-- Instantiate magnetometer plugin. -->
  <gazebo>
    <plugin filename="libgazebo_magnetometer_plugin.so" name="magnetometer_plugin">
      <robotNamespace></robotNamespace>
      <pubRate>50</pubRate>
      <noiseDensity>0.0004</noiseDensity>
      <randomWalk>6.4e-06</randomWalk>
      <biasCorrelationTime>600</biasCorrelationTime>
      <magTopic>/mag</magTopic>
    </plugin>
  </gazebo>
  <!-- Instantiate barometer plugin. -->
  <gazebo>
    <plugin filename="libgazebo_barometer_plugin.so" name="barometer_plugin">
      <robotNamespace></robotNamespace>
      <pubRate>50</pubRate>
      <baroTopic>/baro</baroTopic>
    </plugin>
  </gazebo>
  <!-- Instantiate mavlink telemetry interface. -->
  <gazebo>
    <plugin filename="libgazebo_mavlink_interface.so" name="mavlink_interface">
      <robotNamespace></robotNamespace>
      <imuSubTopic>/imu</imuSubTopic>
      <gpsSubTopic>/gps</gpsSubTopic>
      <magSubTopic>/mag</magSubTopic>
      <baroSubTopic>/baro</baroSubTopic>
      <mavlink_addr>INADDR_ANY</mavlink_addr>
      <mavlink_udp_port>14560</mavlink_udp_port>
      <mavlink_tcp_port>4560</mavlink_tcp_port>
      <serialEnabled>false</serialEnabled>
      <serialDevice>/dev/ttyACM0</serialDevice>
      <baudRate>921600</baudRate>
      <qgc_addr>INADDR_ANY</qgc_addr>
      <qgc_udp_port>14550</qgc_udp_port>
      <sdk_addr>INADDR_ANY</sdk_addr>
      <sdk_udp_port>14540</sdk_udp_port>
      <hil_mode>false</hil_mode>
      <hil_state_level>false</hil_state_level>
      <vehicle_is_tailsitter>false</vehicle_is_tailsitter>
      <send_vision_estimation>true</send_vision_estimation>
      <send_odometry>false</send_odometry>
      <enable_lockstep>false</enable_lockstep>
      <use_tcp>true</use_tcp>
      <motorSpeedCommandPubTopic>/gazebo/command/motor_speed</motorSpeedCommandPubTopic>
      <control_channels>
        <channel name="rotor1">
          <input_index>0</input_index>
          <input_offset>0</input_offset>
          <input_scaling>470</input_scaling>
          <zero_position_disarmed>0</zero_position_disarmed>
          <zero_position_armed>100</zero_position_armed>
          <joint_control_type>velocity</joint_control_type>
        </channel>
        <channel name="rotor2">
          <input_index>1</input_index>
          <input_offset>0</input_offset>
          <input_scaling>470</input_scaling>
          <zero_position_disarmed>0</zero_position_disarmed>
          <zero_position_armed>100</zero_position_armed>
          <joint_control_type>velocity</joint_control_type>
        </channel>
        <channel name="rotor3">
          <input_index>2</input_index>
          <input_offset>0</input_offset>
          <input_scaling>470</input_scaling>
          <zero_position_disarmed>0</zero_position_disarmed>
          <zero_position_armed>100</zero_position_armed>
          <joint_control_type>velocity</joint_control_type>
        </channel>
        <channel name="rotor4">
          <input_index>3</input_index>
          <input_offset>0</input_offset>
          <input_scaling>470</input_scaling>
          <zero_position_disarmed>0</zero_position_disarmed>
          <zero_position_armed>100</zero_position_armed>
          <joint_control_type>velocity</joint_control_type>
        </channel>
        <channel name="rotor4">
          <input_index>4</input_index>
          <input_offset>0</input_offset>
          <input_scaling>470</input_scaling>
          <zero_position_disarmed>0</zero_position_disarmed>
          <zero_position_armed>100</zero_position_armed>
          <joint_control_type>velocity</joint_control_type>
        </channel>
        <channel name="rotor5">
          <input_index>5</input_index>
          <input_offset>0</input_offset>
          <input_scaling>470</input_scaling>
          <zero_position_disarmed>0</zero_position_disarmed>
          <zero_position_armed>100</zero_position_armed>
          <joint_control_type>velocity</joint_control_type>
        </channel>
      </control_channels>
    </plugin>
  </gazebo>
  <!-- Mount an ADIS16448 IMU. -->
  <!-- IMU link -->
  <link name="/imu_link">
    <inertial>
      <inertia ixx="0.00001" ixy="0.0" ixz="0.0" iyy="0.00001" iyz="0.0" izz="0.00001"/>
      <mass value="0.015"/>
      <!-- [kg] -->
      <origin rpy="0 0 0" xyz="0 0 0"/>
    </inertial>
  </link>
  <!-- IMU joint -->
  <joint name="/imu_joint" type="revolute">
    <origin rpy="0 0 0" xyz="0 0 0"/>
    <parent link="base_link"/>
    <child link="/imu_link"/>
    <limit effort="0" lower="0" upper="0" velocity="0"/>
  </joint>
  <gazebo>
    <plugin filename="libgazebo_imu_plugin.so" name="rotors_gazebo_imu_plugin">
      <!-- A good description of the IMU parameters can be found in the kalibr documentation:
           https://github.com/ethz-asl/kalibr/wiki/IMU-Noise-Model-and-Intrinsics -->
      <robotNamespace></robotNamespace>
      <!-- (string, required): ros namespace in which the messages are published -->
      <linkName>/imu_link</linkName>
      <!-- (string, required): name of the body which holds the IMU sensor -->
      <imuTopic>/imu</imuTopic>
      <!-- (string): name of the sensor output topic and prefix of service names (defaults to imu) -->
      <gyroscopeNoiseDensity>0.00018665</gyroscopeNoiseDensity>
      <!-- Gyroscope noise density (two-sided spectrum) [rad/s/sqrt(Hz)] -->
      <gyroscopeRandomWalk>3.8785e-05</gyroscopeRandomWalk>
      <!-- Gyroscope bias random walk [rad/s/s/sqrt(Hz)] -->
      <gyroscopeBiasCorrelationTime>1000.0</gyroscopeBiasCorrelationTime>
      <!-- Gyroscope bias correlation time constant [s] -->
      <gyroscopeTurnOnBiasSigma>0.0087</gyroscopeTurnOnBiasSigma>
      <!-- Gyroscope turn on bias standard deviation [rad/s] -->
      <accelerometerNoiseDensity>0.00186</accelerometerNoiseDensity>
      <!-- Accelerometer noise density (two-sided spectrum) [m/s^2/sqrt(Hz)] -->
      <accelerometerRandomWalk>0.006</accelerometerRandomWalk>
      <!-- Accelerometer bias random walk. [m/s^2/s/sqrt(Hz)] -->
      <accelerometerBiasCorrelationTime>300.0</accelerometerBiasCorrelationTime>
      <!-- Accelerometer bias correlation time constant [s] -->
      <accelerometerTurnOnBiasSigma>0.196</accelerometerTurnOnBiasSigma>
      <!-- Accelerometer turn on bias standard deviation [m/s^2] -->
    </plugin>
  </gazebo>
  <!-- Enable LiDAR -->
  <!-- Instantiate LiDAR plugin -->
  <link name="lidar_lite::link">
    <visual>
      <origin rpy="0 0 0" xyz="0 0 0"/>
      <geometry>
        <mesh filename="package://airfly_hexa/meshes/Lidar_Lite_Laser_Optics.STL" scale="0.002 0.002 0.002"/>
      </geometry>
      <material name="white"/>
    </visual>
    <inertial>
      <mass value="0.01"/>
      <origin rpy="0 0 0" xyz="0 0 0"/>
      <inertia ixx="2.1733e-6" ixy="0" ixz="0" iyy="2.1733e-6" iyz="0" izz="1.8e-7"/>
    </inertial>
  </link>
  <joint name="lidar_joint" type="revolute">
    <origin rpy="0 0 0" xyz="0 0 -0.36"/>
    <parent link="base_link"/>
    <child link="lidar_lite::link"/>
    <axis xyz="0 0 1"/>
    <limit effort="0" lower="0" upper="0" velocity="0"/>
  </joint>
  <gazebo reference="lidar_lite::link">
    <sensor name="laser" type="ray">
      <pose>0 0 -0.21 0 1.57079633 0</pose>
      <ray>
        <scan>
          <horizontal>
            <samples>1</samples>
            <resolution>1</resolution>
            <min_angle>-0</min_angle>
            <max_angle>0</max_angle>
          </horizontal>
        </scan>
        <range>
          <min>0.06</min>
          <!-- do not change: use min_distance (below) for realistic behavior (smaller values cause issues) -->
          <max>35</max>
          <!-- do not change: use min_distance (below) for realistic behavior (bigger values cause issues) -->
          <resolution>0.01</resolution>
        </range>
        <noise>
          <type>gaussian</type>
          <mean>0.0</mean>
          <stddev>0.02</stddev>
        </noise>
      </ray>
      <plugin filename="libgazebo_lidar_lite_plugin.so" name="LaserLitePlugin">
        <robotNamespace/>
        <min_distance>0.08</min_distance>
        <max_distance>30.0</max_distance>
      </plugin>
      <always_on>1</always_on>
      <update_rate>20</update_rate>
      <visualize>true</visualize>
    </sensor>
    <material>Gazebo/White</material>
  </gazebo>
  <!-- Enable GroundTruth -->
  <!-- Instantiate GroundTruth plugin. -->
  <gazebo>
    <plugin filename="libgazebo_ros_p3d.so" name="ground_truth">
      <frameName>map</frameName>
      <bodyName>base_link</bodyName>
      <topicName>/ground_truth</topicName>
      <updateRate>30</updateRate>
      <xyzOffset>0 0 -0.1975016</xyzOffset>
      <rpyOffset>0 0 0</rpyOffset>
    </plugin>
  </gazebo>
</robot>
